Workbook

Sheet Prd Code
A1: Prd Code | B1: Product Name | C1: size | D1: Material | E1: Aug stock | F1: left stock | G1: Kit name
A2: PM-00701 | B2: SeaSoul Niacinamide Dual Serum | C2: 1 gm | D2: Amp | E2: 20000 | F2: =E2-'Wed Glow'!F9 -> 19994
A3: PM-00702 | B3: 95% Pure Hyaluronic Exosome Shot | C3: 1 gm | D3: Amp | E3: 20000 | F3: =E3-'Adv Kor'!F12 -> 19994
A4: PM-00703 | B4: 99% Pure Vitamin C Exosome Shot Serum | C4: 1 gm | D4: Amp | E4: 20000 | F4: =E4-'Ete Bride'!F12 -> 19994
A5: PM-00704 | B5: SeaSoul Retinol Dual Serum | C5: 1 gm | D5: Amp | E5: 20000
A6: PM-00705 | B6: lip lightening peel | C6: 1 ml | D6: Amp | E6: 53000 | F6: =E6-'Ete Bride'!F7-'Adv Kor'!F8-'Wed Glow'!F5 -> 49988
A7: PM-00706 | B7: depigmentation eye gel | C7: 1ml | D7: Amp | E7: 60000 | F7: =E7-'Ete Bride'!F6-'Adv Kor'!F9-'Wed Glow'!F6 -> 59982
A8: PM-00707 | B8: Vitamin C Whitening Cream with SPF 50 | C8: 1 gm | D8: Amp | E8: 50000 | F8: ='Prd Code'!E8-'Adv Kor'!F13-'Adv Kor'!F22-'Ete Bride'!F13-'Wed Glow'!F19 -> 49976
A9: PM-00708 | B9: SeaSoul SFP 30 Cica Gel | C9: 1 gm | D9: Amp | E9: 50000 | F9: =E9-'Ete Bride'!F22-'Wed Glow'!F10 -> 49988
A10: PM-00709 | B10: Dead Sea Face Moisturiser | C10: 2 ml | D10: Amp | E10: 50000 | F10: =E10-'Wed Glow'!F18 -> 49994
A11: PM-00710 | B11: Dead Sea Oil Free Hydrator | C11: 2 ml | D11: Amp | E11: 50000 | F11: =E11-'Adv Kor'!F21-'Ete Bride'!F21 -> 49988
A12: PM-00711 | B12: Dead Sea Anti Ageing Cream | C12: 2 ml | D12: Amp | E12: 50000
A13: PM-00712 | B13: Dead Sea Clarifying Serum | C13: 2 ml | D13: Amp | E13: 50000
A14: PM-00713 | B14: Dead Sea Ultra Hydrating Serum | C14: 2 ml | D14: Amp | E14: 50000 | F14: ='Prd Code'!E14-'Adv Kor'!F20 -> 49994
A15: PM-00714 | B15: Dead Sea Pore Minimising Serum | C15: 2 ml | D15: Amp | E15: 50000 | F15: =E15-'Ete Bride'!F20 -> 49994
A16: PM-00715 | B16: Dead Sea Depigmentation Serum | C16: 2 ml | D16: Amp | E16: 50000 | F16: =E16-'Wed Glow'!F17 -> 49994
A17: PM-00716 | B17: Butter Cream Powder-white- Anti Tan, niacinamide | C17: 1 ml | D17: Amp | E17: 20000 | F17: =E17-'Wed Glow'!F3 -> 19994
A18: PM-00717 | B18: Butter Cream Powder-blue-hyaluronic | C18: 1 ml | D18: Amp
A19: PM-00718 | B19: Butter Cream Powder-yellow-vitaminC | C19: 1 ml | D19: Amp
A20: PM-00719 | B20: PHA Activation Peel | C20: 2ml | D20: bottle | E20: 1000
A21: PM-00720 | B21: Vit C + CICA Peel | C21: 2ml | D21: bottle | E21: 1000
A22: PM-00721 | B22: AHA + BHA + PHA Peel | C22: 2ml | D22: bottle | E22: 1000
A23: PM-00722 | B23: PHA Derma Peel | C23: 2ml | D23: bottle | E23: 1000
A24: PM-00723 | B24: Alpha Beta Activation Peel | C24: 2ml | D24: bottle | E24: 3000
A25: PM-00724 | B25: AHA DNA Peel | C25: 2ml | D25: bottle | E25: 1000
A26: PM-00725 | B26: Korean Glass Pore minimising Serum | C26: 2 ml | D26: bottle | E26: 12000
A27: PM-00726 | B27: Brightening AHA Peel | C27: 4 ml | D27: bottle | E27: 15000
A28: PM-00727 | B28: Dissolve Mask Spray | C28: 10 ml | D28: bottle | E28: 4000 | F28: =E28-'Ete Bride'!F10 -> 3994
A29: PM-00728 | B29: Blackhead Remover Serum | C29: 10 ml | D29: bottle | E29: 6000 | F29: =E29-'Adv Kor'!F14-'Ete Bride'!F14-'Wed Glow'!F11 -> 5997
A30: PM-00729 | B30: Dead Sea pH Face Toner | C30: 10 ml | D30: bottle | E30: 10000 | F30: =E30-'Adv Kor'!F19-'Ete Bride'!F19-'Wed Glow'!F16 -> 9982
A31: PM-00730 | B31: spatula | C31: 1 | D31: pc | E31: 20000 | F31: =E31-'Adv Kor'!F15-'Ete Bride'!F15-'Wed Glow'!F12 -> 19997
A32: PM-00731 | B32: mixing plate / measuring cup | C32: 1 | D32: cup | E32: 13400 | F32: =E32-'Adv Kor'!F16-'Ete Bride'!F16-'Wed Glow'!F13 -> 13397
A33: PM-00732 | B33: derma plan tool | C33: 1 | D33: tool | E33: 10000 | F33: =E33-'Adv Kor'!F17-'Ete Bride'!F17-'Wed Glow'!F14 -> 9997
A34: PM-00733 | B34: alcohol swabs | C34: 1 | D34: sachet | E34: 19700 | F34: =E34-'Adv Kor'!F18-'Ete Bride'!F18-'Wed Glow'!F15 -> 19682
A35: PM-00734 | B35: silk sheet Mask | C35: 1 | D35: sheet | E35: 38800
A36: PM-00735 | B36: Dissolve collagen Mask blue sheet | C36: 1 | D36: blue sheet | E36: 4800
A37: PM-00736 | B37: Glass Mask paper sheet | C37: 1 | D37: white thick sheet | E37: 5000
A38: PM-00390 | B38: Korean Foaming Oil Cleanser | C38: 5 ml | D38: 80 x 80 | E38: 8000 | F38: ='Prd Code'!E38-'Adv Kor'!F3 -> 7994
A39: PM-00391 | B39: PDRN Gel Cleanser | C39: 5 ml | D39: 80 x 80 | E39: 8000 | F39: ='Prd Code'!E39-'Adv Kor'!F4 -> 7994
A40: PM-00392 | B40: Korean Collagen Glass Glow Peel Disc | C40: 1 | D40: 80 x 80 | E40: 8125 | F40: ='Prd Code'!E40-'Adv Kor'!F5 -> 8119
...

Sheet Sachet
A1: # | B1: Item Code | C1: Item Name | D1: Sachet
A2: 1 | B2: PM-00390 | C2: Step-(1) Korean Foaming Oil Cleanser Sachet | D2: 8000
A3: 2 | B3: PM-00391 | C3: Step-(2) PDRN Gel Cleanser Sachet | D3: 8000
A4: 3 | B4: PM-00392 | C4: Step-(3a) Korean Collagen Glass Glow Peel Disc Sachet | D4: 8125
A5: 4 | B5: PM-00393 | C5: Step-(3b) Korean Glass Glow Mixing Serum Sachet | D5: 8125
A6: 5 | B6: PM-00394 | C6: Step-(4) Korean Skin Lightening Scrub Sachet | D6: 8125
A7: 6 | B7: PM-00395 | C7: Step-(7) PDRN Massage Gel Creme Sachet | D7: 8125
A8: 7 | B8: PM-00396 | C8: Step-(2) Ubtan Skin Brightening Scrub Sachet | D8: 6875
A9: 8 | B9: PM-00397 | C9: Step-(5) Niacinamide Squalene Massage Cream Sachet | D9: 7500
A10: 9 | B10: PM-00376 | C10: Step-(1a) Dead Sea Mani Pedi Soak Sachet | D10: 7875
A11: 10 | B11: PM-00377 | C11: Step-(1b) Exosomes Mani Pedi Mineral Dip Sachet(DSATMP) | D11: 7875
A12: 11 | B12: PM-00378 | C12: Step-(2) Cutical Remover Cream Sachet(DSATMP) | D12: 7500
A13: 12 | B13: PM-00379 | C13: Step-(4) Dead Sea Aqua Candle Exfoliator Sachet (DSATMP) | D13: 7500
... A71: 70 | B71: PM-00570 | C71: Step-(1) Soap Cleanser Gold Morocan Vit-C Facial Kit Sachet | D71: 15625

Sheet Blister
A1: S.No. | B1: Item code | C1: Item name | D1: Stock | E1: Kits
A2: 1 | B2: PM-00443 | C2: Blister Tray Small Size 143mm x 106mm | D2: 36300 | E2: dead sea anti tan Mani Pedi
A3: 2 | B3: PM-00374 | C3: Blister Tray (500micron, APET 49 box 4001 box 250) | D3: 19850 | E3: Wedding , advance Korean, eternal bride
A4: 3 | B4: PM-00598 | C4: PVC Box-300 micron | D4: 21810
A5: 4 | B5: PM-00652 | C5: Plastic Container Cup Cake | D5: 25000
A6: 5 | B6: PM-00653 | C6: Plastic Container Wine Glass | D6: 12000
A7: 6 | B7: PM-00581 | C7: Blister Tray Small Size 145mm X 117mm | D7: 0 | E7: Candle spa Mani Pedi
A8: 7 | B8: PM-00582 | C8: Blister Tray Size 132mmX132mm | D8: 12180 | E8: KOrean No More Tan MP

Sheet packaging
A1: Item Code | B1: Item Name | C1: Stock
A2: PM-00443 | B2: Blister Tray Small Size 143mm x 106mm | C2: 36300 | F2: dead sea Anti Tan Mani Pedi
A3: PM-00374 | B3: Blister Tray (500micron, APET 49 box 4001 box 250) | C3: 19850 | F3: Facial kits
A4: PM-00598 | B4: PVC Box-300 micron | C4: =15810+6000 -> 21810
A5: PM-00871 | B5: Blister Tray Small Size 145mm X 117mm | C5: 0
A6: PM-00872 | B6: Blister Tray Size 132mmX132mm | C6: 12180
A7: PM-00652 | B7: Plastic Container Cup Cake | C7: 8000
A8: PM-00653 | B8: Plastic Container Wine Glass | C8: 12000
A9: PM-00517 | B9: Advanced Korean PDRN Facial Kit-Outer Bottom | C9: 1114
A10: PM-00516 | B10: Advanced Korean PDRN Facial Kit-Outer Top | C10: 1120
A11: PM-00515 | B11: Advanced Korean PDRN Facial Kit-sleeve | C11: 6400
A12: PM-00507 | B12: Eternal Bride Vit c Facial Kit Outer Bottom | C12: 1100
A13: PM-00508 | B13: Eternal Bride Vit c Facial Kit Outer Top | C13: 1035
A14: PM-00509 | B14: Eternal Bride Vit c Facial Kit Sleeve | C14: 6408
A15: PM-00615 | B15: Home care Anti Agening Monocarton | C15: 9800
A16: PM-00616 | B16: Home care kit Glow Kit Anti Monocarton | C16: 9932
... A92: PM-00859 | B92: Bombshell High Tea Mani Pedi Wine & Cheese - outerbox | C92: 0
A93: PM-00860 | B93: Candle Spa Mani Pedi- Outer Bottom | C93: 0 | D93: 0
A94: PM-00861 | B94: Candle Spa Mani Pedi- Outer Top
A95: PM-00862 | B95: Candle Spa Mani Pedi- Sleeve | C95: 0
A96: PM-00863 | B96: Basic Organic Mani Pedi- Monocarton | C96: 0
A97: PM-00864 | B97: Basic Organic Mani Pedi- Outer Box | C97: 0
A98: PM-00865 | B98: Choco Moringa Mani Pedi- Monocarton | C98: 0
A99: PM-00866 | B99: Choco Moringa Mani Pedi- Outer Box | C99: 0
A100: PM-00867 | B100: Brazilian Clean Up- Monocarton | C100: 0
A101: PM-00868 | B101: Brazilian Clean Up- Outer Box | C101: 0
A102: PM-00869 | B102: Body Spa Kit- Monocarton | C102: 0
A103: PM-00870 | B103: Body Spa Kit- Outer Box | C103: 0

Sheet RM
C1: qty in gms | D1: current qty in KG
A2: RM-00362 | B2: Sodium Alginate Yellow | C2: =D2*1000 -> 499000 | D2: 499
A3: RM-00363 | B3: Sodium Alginate Blue | C3: =D3*1000 -> 999000 | D3: 999
A4: RM-00364 | B4: Sodium Alginate Dark Yellow (Gold) | C4: =D4*1000 -> 1996000 | D4: 1996
A5: RM-00365 | B5: Sodium Alginate Pink | C5: =D5*1000 -> 674000 | D5: =799-125 -> 674
A6: RM-00366 | B6: Sodium Alginate Orange | C6: =D6*1000 -> 374000 | D6: =499-125 -> 374
A7: RM-00367 | B7: Sodium Alginate White | C7: =D7*1000 -> 691000 | D7: =799-108 -> 691
A8: RM-00368 | B8: Sodium Alginate Gray | C8: =D8*1000 -> 387000 | D8: =399-12 -> 387
B9: Silk Mask Sheet | D9: 38800

Sheet Adv Kor
B1: Advance Korean PDRN Facial Kit | F1: current order
A2: Prd code | B2: SNO. | C2: Product Name | D2: Content | E2: pcs/ kit | F2: 1
A3: ='Prd Code'!#REF! -> #REF! | B3: 1 | C3: Korean Foaming Oil Cleanser | D3: 5 ml | E3: 6 | F3: =E3*$F$2 -> 6
A4: ='Prd Code'!#REF! -> #REF! | B4: 2 | C4: PDRN Gel Cleanser | D4: 5 ml | E4: 6 | F4: =E4*$F$2 -> 6
A5: ='Prd Code'!#REF! -> #REF! | B5: 3a | C5: Korean Collagen Glass Glow Peel | D5: 1 disc | E5: 6 | F5: =E5*$F$2 -> 6
A6: ='Prd Code'!#REF! -> #REF! | B6: 3b | C6: Korean Glass Glow Mixing Serum | D6: 8 ml | E6: 6 | F6: =E6*$F$2 -> 6
A7: ='Prd Code'!#REF! -> #REF! | B7: 4 | C7: Korean Skin Lightening Scrub | D7: 10 ml | E7: 6 | F7: =E7*$F$2 -> 6
A8: ='Prd Code'!A6 -> PM-00705 | B8: 5 | C8: lip lightening peel | D8: 2ml | E8: 6 | F8: 3000
A9: ='Prd Code'!A7 -> PM-00706 | B9: 6 | C9: depigmentation eye serum | D9: 2ml | E9: 6 | F9: =E9*$F$2 -> 6
A10: ='Prd Code'!#REF! -> #REF! | B10: 7 | C10: PDRN Massage Gel Crème | D10: 10 ml | E10: 6 | F10: =E10*$F$2 -> 6
A11: ='Prd Code'!A44 -> PM-00413 | B11: 8 | C11: Hydra Glow PDRN Glass Mask | D11: 1 | E11: 6 | F11: =E11*$F$2 -> 6
A12: ='Prd Code'!A3 -> PM-00702 | B12: 9 | C12: 95% Pure Hyaluronic Exosome Shot | D12: 1 | E12: 6 | F12: =E12*$F$2 -> 6
A13: ='Prd Code'!A8 -> PM-00707 | B13: 10 | C13: Vitamin C Whitening Cream with SPF 50 | D13: 2ml | E13: 6 | F13: =E13*$F$2 -> 6
A14: ='Prd Code'!A29 -> PM-00728 | B14: Facial tools kit | C14: blackhead softener | D14: 5 ml | E14: 1 | F14: =E14*$F$2 -> 1
A15: ='Prd Code'!A31 -> PM-00730 | C15: spatula | D15: 1 | E15: 1 | F15: =E15*$F$2 -> 1
A16: ='Prd Code'!A32 -> PM-00731 | C16: mixing plate | D16: 1 | E16: 1 | F16: =E16*$F$2 -> 1
A17: ='Prd Code'!A33 -> PM-00732 | C17: derma plan tool | D17: 1 | E17: 1 | F17: =E17*$F$2 -> 1
A18: ='Prd Code'!A34 -> PM-00733 | C18: alcohol swabs | D18: 1 | E18: 6 | F18: =E18*$F$2 -> 6
A19: ='Prd Code'!A30 -> PM-00729 | B19: Home Care Kit | C19: Dead Sea pH Face Toner | D19: 1 | E19: 6 | F19: =E19*$F$2 -> 6
A20: ='Prd Code'!A14 -> PM-00713 | C20: Dead Sea Ultra Hydration Serum | D20: 1 | E20: 6 | F20: =E20*$F$2 -> 6
A21: ='Prd Code'!A11 -> PM-00710 | C21: Deas Sea Oil free hydrator | D21: 1 | E21: 6 | F21: =E21*$F$2 -> 6
A22: ='Prd Code'!A8 -> PM-00707 | C22: Vitamin C Whitening Cream with SPF 50 | D22: 1 | E22: 6 | F22: =E22*$F$2 -> 6

Sheet Ete Bride
B1: Eternal Bride Vitamin C Facial Kit | F1: current order
A2: Prd code | B2: Step NO. | C2: Product Name | D2: Content | E2: pcs/ kit | F2: 1
A3: ='Prd Code'!#REF! -> #REF! | B3: 1 | C3: Vitamin C Foaming Oil Cleanser | D3: 5 ml | E3: 6 | F3: =E3*$F$2 -> 6
A4: ='Prd Code'!#REF! -> #REF! | B4: 2 | C4: Vitamin C gel cleanser | D4: 5 ml | E4: 6 | F4: =E4*$F$2 -> 6
A5: ='Prd Code'!#REF! -> #REF! | B5: 3 | C5: Vatna skin brightening Scrub | D5: 10 ml | E5: 6 | F5: =E5*$F$2 -> 6
A6: ='Prd Code'!A7 -> PM-00706 | B6: 4 | C6: de pigmentation Eye serum | D6: 2 ml | E6: 6 | F6: =E6*$F$2 -> 6
A7: ='Prd Code'!A6 -> PM-00705 | B7: 5 | C7: Lip Lightening peel | D7: 2 ml | E7: 6 | F7: =E7*$F$2 -> 6
A8: ='Prd Code'!#REF! -> #REF! | B8: 6 | C8: Vitamin C Squalene Massage Cream | D8: 10 ml | E8: 6 | F8: =E8*$F$2 -> 6
A9: ='Prd Code'!A49 -> PM-00414 | B9: 7a | C9: Collagen dissolve mask sheet | D9: 1 | E9: 6 | F9: =E9*$F$2 -> 6
A10: ='Prd Code'!A28 -> PM-00727 | B10: 7b | C10: Dissolve Mask Spray | D10: 10 ml | E10: 6 | F10: =E10*$F$2 -> 6
A11: ='Prd Code'!#REF! -> #REF! | B11: 8 | C11: Ultra Brightening Rose Petal Jelly Mask | D11: 40 gm | E11: 6 | F11: =E11*$F$2 -> 6
A12: ='Prd Code'!A4 -> PM-00703 | B12: 9 | C12: 99% Pure Vitamin C Exosome Shot Serum | D12: 1 | E12: 6 | F12: =E12*$F$2 -> 6
A13: ='Prd Code'!A8 -> PM-00707 | B13: 10 | C13: Vitamin C Whitening Cream with SPF50 | D13: 2ml | E13: 6 | F13: =E13*$F$2 -> 6
A14: ='Prd Code'!A29 -> PM-00728 | B14: Facial tools kit | C14: blackhead softener | D14: 5 ml | E14: 1 | F14: =E14*$F$2 -> 1
A15: ='Prd Code'!A31 -> PM-00730 | C15: spatula | D15: 1 | E15: 1 | F15: =E15*$F$2 -> 1
A16: ='Prd Code'!A32 -> PM-00731 | C16: Measuring cup | D16: 1 | E16: 1 | F16: =E16*$F$2 -> 1
A17: ='Prd Code'!A33 -> PM-00732 | C17: derma plan tool | D17: 1 | E17: 1 | F17: =E17*$F$2 -> 1
A18: ='Prd Code'!A34 -> PM-00733 | C18: alcohol swabs | D18: 1 | E18: 6 | F18: =E18*$F$2 -> 6
A19: ='Prd Code'!A30 -> PM-00729 | B19: Home Care Kit - Pore Minimising | C19: Dead Sea pH Face Toner | D19: 1 | E19: 6 | F19: =E19*$F$2 -> 6
A20: ='Prd Code'!A15 -> PM-00714 | C20: Dead Sea Pore MInimising Serum | D20: 1 | E20: 6 | F20: =E20*$F$2 -> 6
A21: ='Prd Code'!A11 -> PM-00710 | C21: Deas Sea Oil free hydrator | D21: 1 | E21: 6 | F21: =E21*$F$2 -> 6
A22: ='Prd Code'!A9 -> PM-00708 | C22: CICA Gel Crème SPF 30 | D22: 1 | E22: 6 | F22: =E22*$F$2 -> 6

Sheet Wed Glow
B1: Eternal Bride Vitamin C Facial Kit | F1: current order
A2: Prd code | B2: Step NO. | C2: Product Name | D2: Content | E2: pcs/ kit | F2: 1
A3: ='Prd Code'!A17 -> PM-00716 | B3: 1 | C3: Niacinamide buttercream cleansing Powder | D3: 1ml | E3: 6 | F3: =E3*$F$2 -> 6
A4: ='Prd Code'!#REF! -> #REF! | B4: 2 | C4: Vatna skin brightening Scrub | D4: 10 ml | E4: 6 | F4: =E4*$F$2 -> 6
A5: ='Prd Code'!A6 -> PM-00705 | B5: 3 | C5: Lip Lightening peel | D5: 2 ml | E5: 6 | F5: =E5*$F$2 -> 6
A6: ='Prd Code'!A7 -> PM-00706 | B6: 4 | C6: de pigmentation Eye serum | D6: 2 ml | E6: 6 | F6: =E6*$F$2 -> 6
A7: ='Prd Code'!#REF! -> #REF! | B7: 5 | C7: Niacinamide Squalene Massage Cream | D7: 10 ml | E7: 6 | F7: =E7*$F$2 -> 6
A8: ='Prd Code'!A53 -> PM-00417 | B8: 6 | C8: Ultra Lightening Orange Peel Jelly Mask | D8: 40 gm | E8: 6 | F8: =E8*$F$2 -> 6
A9: ='Prd Code'!A2 -> PM-00701 | B9: 7 | C9: 99.5% Pure Niacinamide PDRN Shot Serum | D9: 1 | E9: 6 | F9: =E9*$F$2 -> 6
A10: ='Prd Code'!A9 -> PM-00708 | B10: 8 | C10: CICA Gel Crème SPF 30 | D10: 2ml | E10: 6 | F10: =E10*$F$2 -> 6
A11: ='Prd Code'!A29 -> PM-00728 | B11: Facial tools kit | C11: blackhead softener | D11: 5 ml | E11: 1 | F11: =E11*$F$2 -> 1
A12: ='Prd Code'!A31 -> PM-00730 | C12: spatula | D12: 1 | E12: 1 | F12: =E12*$F$2 -> 1
A13: ='Prd Code'!A32 -> PM-00731 | C13: Measuring cup | D13: 1 | E13: 1 | F13: =E13*$F$2 -> 1
A14: ='Prd Code'!A33 -> PM-00732 | C14: derma plan tool | D14: 1 | E14: 1 | F14: =E14*$F$2 -> 1
A15: ='Prd Code'!A34 -> PM-00733 | C15: alcohol swabs | D15: 1 | E15: 6 | F15: =E15*$F$2 -> 6
A16: ='Prd Code'!A30 -> PM-00729 | B16: Home Care Kit | C16: Dead Sea pH Face Toner | D16: 1 | E16: 6 | F16: =E16*$F$2 -> 6
A17: ='Prd Code'!A16 -> PM-00715 | C17: Dead Sea depigmentation Serum | D17: 1 | E17: 6 | F17: =E17*$F$2 -> 6
A18: ='Prd Code'!A10 -> PM-00709 | C18: Dead Sea Face moisturiser | D18: 1 | E18: 6 | F18: =E18*$F$2 -> 6
A19: ='Prd Code'!A8 -> PM-00707 | C19: Vitamin C Whitening Cream with SPF 50 | D19: 1 | E19: 6 | F19: =E19*$F$2 -> 6
